<mujoco model="cartpole">
  <compiler angle="radian" inertiafromgeom="true"/>
  
  <visual>
    <global offwidth="1024" offheight="768"/>
  </visual>
  
  <default>
    <joint armature="0" damping="0.1" limited="true"/>
    <geom conaffinity="0" condim="3" contype="1" friction="1 0.1 0.1" 
          rgba="0.8 0.6 0.4 1" density="1000"/>
  </default>

  <option gravity="0 0 -9.81" integrator="RK4" timestep="0.01"/>

  <worldbody>
    <light cutoff="100" diffuse="1 1 1" dir="-0 0 -1.3" directional="true" 
          exponent="1" pos="0 0 1.3" specular=".1 .1 .1"/>
    
    <geom name="floor" pos="0 0 -0.6" size="2.5 2.5 0.05" type="plane" 
          rgba="0.9 0.9 0.9 1"/>
    
    <geom name="rail1" type="capsule" pos="0  0.07 0" size="0.02 1" 
          rgba="0.3 0.3 0.7 1"/>
    <geom name="rail2" type="capsule" pos="0 -0.07 0" size="0.02 1" 
          rgba="0.3 0.3 0.7 1"/>
    
    <body name="cart" pos="0 0 0">
      <joint name="slider" type="slide" pos="0 0 0" axis="1 0 0" 
             range="-1 1" damping="0.1"/>
      <geom name="cart" type="box" pos="0 0 0" size="0.2 0.15 0.1" 
            rgba="0.2 0.8 0.2 1" mass="1"/>
      
      <body name="pole" pos="0 0 0">
        <joint name="hinge" type="hinge" pos="0 0 0" axis="0 1 0" 
               range="-3.14 3.14" damping="0.01"/>
        <geom name="cpole" type="capsule" fromto="0 0 0 0 0 0.6" 
              size="0.045" rgba="0.8 0.2 0.2 1" mass="0.1"/>
        <geom name="ball" type="sphere" pos="0 0 0.6" size="0.08" 
              rgba="0.8 0.2 0.2 1" mass="0.05"/>
      </body>
    </body>
  </worldbody>

  <actuator>
    <motor joint="slider" gear="100" ctrllimited="true" ctrlrange="-10 10"/>
  </actuator>
</mujoco>
